Using device: cuda
[*********************100%***********************]  1 of 1 completed
Ticker            AAPL
Date
2012-05-18   15.978591
2012-05-21   16.909508
2012-05-22   16.779663
2012-05-23   17.189083
2012-05-24   17.031216
...                ...
2023-05-24  170.546951
2023-05-25  171.688324
2023-05-26  174.109924
2023-05-30  175.965866
2023-05-31  175.916275

[2776 rows x 1 columns]
/data/student/k2110261/Multi-iTransformer/optunademo.py:104: FutureWarning: Series.fillna with 'method' is deprecated and will raise in a future version. Use obj.ffill() or obj.bfill() instead.
  df = df.fillna(method='ffill')  # 前日のデータを使用
{'AAPL': Date
2012-05-18     18.353259
2012-05-21     18.337500
2012-05-22     18.321752
2012-05-23     18.306015
2012-05-24     18.290289
                 ...
2023-05-24    161.245409
2023-05-25    161.302981
2023-05-26    161.360548
2023-05-30    161.418112
2023-05-31    161.475672
Name: trend, Length: 2776, dtype: float64, 'DTWEXBGS': Date
2012-05-18     93.1395
2012-05-21     93.0945
2012-05-22     93.1113
2012-05-23     93.8855
2012-05-24     93.8027
                ...
2023-05-24    120.6481
2023-05-25    121.0126
2023-05-26    120.8022
2023-05-30    120.7387
2023-05-31    121.1527
Length: 2776, dtype: float64, 'VIXCLS': Date
2012-05-18    25.10
2012-05-21    22.01
2012-05-22    22.48
2012-05-23    22.33
2012-05-24    21.54
              ...
2023-05-24    20.03
2023-05-25    19.14
2023-05-26    17.95
2023-05-30    17.46
2023-05-31    17.94
Length: 2776, dtype: float64, 'DFII10': Date
2012-05-18   -0.39
2012-05-21   -0.41
2012-05-22   -0.38
2012-05-23   -0.41
2012-05-24   -0.37
              ...
2023-05-24    1.48
2023-05-25    1.58
2023-05-26    1.57
2023-05-30    1.47
2023-05-31    1.46
Length: 2776, dtype: float64, 'T10Y2Y': Date
2012-05-18    1.39
2012-05-21    1.45
2012-05-22    1.49
2012-05-23    1.45
2012-05-24    1.48
              ...
2023-05-24   -0.58
2023-05-25   -0.67
2023-05-26   -0.74
2023-05-30   -0.77
2023-05-31   -0.76
Length: 2776, dtype: float64}
AAPLにあるが他のデータ1にはない日付: DatetimeIndex([], dtype='datetime64[ns]', name='Date', freq=None)
他のデータ1にあるがAAPLにはない日付: DatetimeIndex([], dtype='datetime64[ns]', name='Date', freq=None)
Price      BB_Upper BB_Lower BB_Middle MACD MACD_Signal MACD_Diff RSI SMA_50 SMA_200
Ticker
Date
2012-05-18      NaN      NaN       NaN  NaN         NaN       NaN NaN    NaN     NaN
2012-05-21      NaN      NaN       NaN  NaN         NaN       NaN NaN    NaN     NaN
2012-05-22      NaN      NaN       NaN  NaN         NaN       NaN NaN    NaN     NaN
2012-05-23      NaN      NaN       NaN  NaN         NaN       NaN NaN    NaN     NaN
2012-05-24      NaN      NaN       NaN  NaN         NaN       NaN NaN    NaN     NaN
['AAPL', 'DTWEXBGS', 'VIXCLS', 'DFII10', 'T10Y2Y', 'volume', 'BB_Upper', 'BB_Lower', 'BB_Middle', 'MACD', 'MACD_Signal', 'MACD_Diff', 'RSI', 'SMA_50', 'SMA_200']
Traceback (most recent call last):
  File "/home2/y2021/k2110261/.conda/envs/tensorflow/lib/python3.11/site-packages/pandas/core/indexes/base.py", line 3805, in get_loc
    return self._engine.get_loc(casted_key)
           ^^^^^^^^^^^^^^^^^^^^^^^^^^^^^^^^
  File "index.pyx", line 167, in pandas._libs.index.IndexEngine.get_loc
  File "index.pyx", line 196, in pandas._libs.index.IndexEngine.get_loc
  File "pandas/_libs/hashtable_class_helper.pxi", line 7081, in pandas._libs.hashtable.PyObjectHashTable.get_item
  File "pandas/_libs/hashtable_class_helper.pxi", line 7089, in pandas._libs.hashtable.PyObjectHashTable.get_item
KeyError: 'volume'

The above exception was the direct cause of the following exception:

Traceback (most recent call last):
  File "/data/student/k2110261/Multi-iTransformer/optunademo.py", line 162, in <module>
    dataframes_trend[ticker] = df_stock[ticker]
                               ~~~~~~~~^^^^^^^^
  File "/home2/y2021/k2110261/.conda/envs/tensorflow/lib/python3.11/site-packages/pandas/core/frame.py", line 4101, in __getitem__
    return self._getitem_multilevel(key)
           ^^^^^^^^^^^^^^^^^^^^^^^^^^^^^
  File "/home2/y2021/k2110261/.conda/envs/tensorflow/lib/python3.11/site-packages/pandas/core/frame.py", line 4159, in _getitem_multilevel
    loc = self.columns.get_loc(key)
          ^^^^^^^^^^^^^^^^^^^^^^^^^
  File "/home2/y2021/k2110261/.conda/envs/tensorflow/lib/python3.11/site-packages/pandas/core/indexes/multi.py", line 3040, in get_loc
    loc = self._get_level_indexer(key, level=0)
          ^^^^^^^^^^^^^^^^^^^^^^^^^^^^^^^^^^^^^
  File "/home2/y2021/k2110261/.conda/envs/tensorflow/lib/python3.11/site-packages/pandas/core/indexes/multi.py", line 3391, in _get_level_indexer
    idx = self._get_loc_single_level_index(level_index, key)
          ^^^^^^^^^^^^^^^^^^^^^^^^^^^^^^^^^^^^^^^^^^^^^^^^^^
  File "/home2/y2021/k2110261/.conda/envs/tensorflow/lib/python3.11/site-packages/pandas/core/indexes/multi.py", line 2980, in _get_loc_single_level_index
    return level_index.get_loc(key)
           ^^^^^^^^^^^^^^^^^^^^^^^^
  File "/home2/y2021/k2110261/.conda/envs/tensorflow/lib/python3.11/site-packages/pandas/core/indexes/base.py", line 3812, in get_loc
    raise KeyError(key) from err
KeyError: 'volume'
