ÊúÄÈÅ©ÂåñÂØæË±°: trend
[32m[I 2025-01-01 17:34:04,587][0m A new study created in memory with name: no-name-4f80f1b6-a1a2-4125-b467-657f1d0e6876[0m
Non-A100 GPU detected, using math or mem efficient attention if input tensor is on cuda
/home2/y2021/k2110261/.conda/envs/tensorflow/lib/python3.11/contextlib.py:105: FutureWarning: `torch.backends.cuda.sdp_kernel()` is deprecated. In the future, this context manager will be removed. Please see `torch.nn.attention.sdpa_kernel()` for the new context manager, with updated signature.
  self.gen = func(*args, **kwds)
[32m[I 2025-01-01 17:34:09,654][0m Trial 0 finished with value: 0.345988392829895 and parameters: {'observation_period_num': 190, 'train_rates': 0.9600249753004666, 'learning_rate': 0.0007208659405103257, 'batch_size': 138, 'step_size': 5, 'gamma': 0.9303254633143551}. Best is trial 0 with value: 0.345988392829895.[0m
trend „ÅÆÊúÄÈÅ©„Éè„Ç§„Éë„Éº„Éë„É©„É°„Éº„Çø„ÅåË¶ã„Å§„Åã„Çä„Åæ„Åó„Åü
ÊúÄÈÅ©ÂåñÂØæË±°: seasonal_0
[32m[I 2025-01-01 17:34:09,655][0m A new study created in memory with name: no-name-51379dc1-ee0b-46c8-9b92-8bce65486f79[0m
[33m[W 2025-01-01 17:34:11,791][0m Trial 0 failed with parameters: {'observation_period_num': 110, 'train_rates': 0.7442049183256136, 'learning_rate': 9.496721065728349e-05, 'batch_size': 82, 'step_size': 8, 'gamma': 0.8034096931303913} because of the following error: RuntimeError('r.nvmlDeviceGetNvLinkRemoteDeviceType_ INTERNAL ASSERT FAILED at "/opt/conda/conda-bld/pytorch_1727971040866/work/c10/cuda/driver_api.cpp":33, please report a bug to PyTorch. Can\'t find nvmlDeviceGetNvLinkRemoteDeviceType: /lib/x86_64-linux-gnu/libnvidia-ml.so.1: undefined symbol: nvmlDeviceGetNvLinkRemoteDeviceType').[0m
Traceback (most recent call last):
  File "/home2/y2021/k2110261/.conda/envs/tensorflow/lib/python3.11/site-packages/optuna/study/_optimize.py", line 197, in _run_trial
    value_or_values = func(trial)
                      ^^^^^^^^^^^
  File "/data/student/k2110261/Multi-iTransformer/roop_optuna_change.py", line 556, in <lambda>
    study.optimize(lambda trial: objective(trial, component, depth, dim), n_trials=1) #check
                                 ^^^^^^^^^^^^^^^^^^^^^^^^^^^^^^^^^^^^^^^
  File "/data/student/k2110261/Multi-iTransformer/roop_optuna_change.py", line 113, in objective
    model, _, valid_loss = train(
                           ^^^^^^
  File "/data/student/k2110261/Multi-iTransformer/src/train.py", line 32, in train
    output = model(data)
             ^^^^^^^^^^^
  File "/home2/y2021/k2110261/.conda/envs/tensorflow/lib/python3.11/site-packages/torch/nn/modules/module.py", line 1736, in _wrapped_call_impl
    return self._call_impl(*args, **kwargs)
           ^^^^^^^^^^^^^^^^^^^^^^^^^^^^^^^^
  File "/home2/y2021/k2110261/.conda/envs/tensorflow/lib/python3.11/site-packages/torch/nn/modules/module.py", line 1747, in _call_impl
    return forward_call(*args, **kwargs)
           ^^^^^^^^^^^^^^^^^^^^^^^^^^^^^
  File "<@beartype(src.model.iTransformer.forward) at 0x7efd47bf9080>", line 66, in forward
  File "/data/student/k2110261/Multi-iTransformer/src/model.py", line 190, in forward
    x = ff(x) + x
        ~~~~~~^~~
RuntimeError: r.nvmlDeviceGetNvLinkRemoteDeviceType_ INTERNAL ASSERT FAILED at "/opt/conda/conda-bld/pytorch_1727971040866/work/c10/cuda/driver_api.cpp":33, please report a bug to PyTorch. Can't find nvmlDeviceGetNvLinkRemoteDeviceType: /lib/x86_64-linux-gnu/libnvidia-ml.so.1: undefined symbol: nvmlDeviceGetNvLinkRemoteDeviceType
[33m[W 2025-01-01 17:34:11,798][0m Trial 0 failed with value None.[0m
Traceback (most recent call last):
  File "/data/student/k2110261/Multi-iTransformer/roop_optuna_change.py", line 556, in <module>
    study.optimize(lambda trial: objective(trial, component, depth, dim), n_trials=1) #check
    ^^^^^^^^^^^^^^^^^^^^^^^^^^^^^^^^^^^^^^^^^^^^^^^^^^^^^^^^^^^^^^^^^^^^^^^^^^^^^^^^^
  File "/home2/y2021/k2110261/.conda/envs/tensorflow/lib/python3.11/site-packages/optuna/study/study.py", line 475, in optimize
    _optimize(
  File "/home2/y2021/k2110261/.conda/envs/tensorflow/lib/python3.11/site-packages/optuna/study/_optimize.py", line 63, in _optimize
    _optimize_sequential(
  File "/home2/y2021/k2110261/.conda/envs/tensorflow/lib/python3.11/site-packages/optuna/study/_optimize.py", line 160, in _optimize_sequential
    frozen_trial = _run_trial(study, func, catch)
                   ^^^^^^^^^^^^^^^^^^^^^^^^^^^^^^
  File "/home2/y2021/k2110261/.conda/envs/tensorflow/lib/python3.11/site-packages/optuna/study/_optimize.py", line 248, in _run_trial
    raise func_err
  File "/home2/y2021/k2110261/.conda/envs/tensorflow/lib/python3.11/site-packages/optuna/study/_optimize.py", line 197, in _run_trial
    value_or_values = func(trial)
                      ^^^^^^^^^^^
  File "/data/student/k2110261/Multi-iTransformer/roop_optuna_change.py", line 556, in <lambda>
    study.optimize(lambda trial: objective(trial, component, depth, dim), n_trials=1) #check
                                 ^^^^^^^^^^^^^^^^^^^^^^^^^^^^^^^^^^^^^^^
  File "/data/student/k2110261/Multi-iTransformer/roop_optuna_change.py", line 113, in objective
    model, _, valid_loss = train(
                           ^^^^^^
  File "/data/student/k2110261/Multi-iTransformer/src/train.py", line 32, in train
    output = model(data)
             ^^^^^^^^^^^
  File "/home2/y2021/k2110261/.conda/envs/tensorflow/lib/python3.11/site-packages/torch/nn/modules/module.py", line 1736, in _wrapped_call_impl
    return self._call_impl(*args, **kwargs)
           ^^^^^^^^^^^^^^^^^^^^^^^^^^^^^^^^
  File "/home2/y2021/k2110261/.conda/envs/tensorflow/lib/python3.11/site-packages/torch/nn/modules/module.py", line 1747, in _call_impl
    return forward_call(*args, **kwargs)
           ^^^^^^^^^^^^^^^^^^^^^^^^^^^^^
  File "<@beartype(src.model.iTransformer.forward) at 0x7efd47bf9080>", line 66, in forward
  File "/data/student/k2110261/Multi-iTransformer/src/model.py", line 190, in forward
    x = ff(x) + x
        ~~~~~~^~~
RuntimeError: r.nvmlDeviceGetNvLinkRemoteDeviceType_ INTERNAL ASSERT FAILED at "/opt/conda/conda-bld/pytorch_1727971040866/work/c10/cuda/driver_api.cpp":33, please report a bug to PyTorch. Can't find nvmlDeviceGetNvLinkRemoteDeviceType: /lib/x86_64-linux-gnu/libnvidia-ml.so.1: undefined symbol: nvmlDeviceGetNvLinkRemoteDeviceType
