ÊúÄÈÅ©ÂåñÂØæË±°: trend
[32m[I 2024-12-29 22:28:29,139][0m A new study created in memory with name: no-name-ad6b876f-120b-4682-bac4-c611320fa248[0m
Non-A100 GPU detected, using math or mem efficient attention if input tensor is on cuda
trend
[33m[W 2024-12-29 22:28:31,670][0m Trial 0 failed with parameters: {'observation_period_num': 172, 'train_rates': 0.6313417381489438, 'learning_rate': 0.0008985637761209667, 'batch_size': 224, 'step_size': 8, 'gamma': 0.8273175377982067} because of the following error: AssertionError().[0m
Traceback (most recent call last):
  File "/home2/y2021/k2110261/.conda/envs/tensorflow/lib/python3.11/site-packages/optuna/study/_optimize.py", line 197, in _run_trial
    value_or_values = func(trial)
                      ^^^^^^^^^^^
  File "/data/student/k2110261/Multi-iTransformer/roop_optuna.py", line 551, in <lambda>
    study.optimize(lambda trial: objective(trial, component, depth, dim), n_trials=30) #check
                                 ^^^^^^^^^^^^^^^^^^^^^^^^^^^^^^^^^^^^^^^
  File "/data/student/k2110261/Multi-iTransformer/roop_optuna.py", line 114, in objective
    model, _, valid_loss = train(
                           ^^^^^^
  File "/data/student/k2110261/Multi-iTransformer/src/train.py", line 32, in train
    output = model(data)
             ^^^^^^^^^^^
  File "/home2/y2021/k2110261/.conda/envs/tensorflow/lib/python3.11/site-packages/torch/nn/modules/module.py", line 1736, in _wrapped_call_impl
    return self._call_impl(*args, **kwargs)
           ^^^^^^^^^^^^^^^^^^^^^^^^^^^^^^^^
  File "/home2/y2021/k2110261/.conda/envs/tensorflow/lib/python3.11/site-packages/torch/nn/modules/module.py", line 1747, in _call_impl
    return forward_call(*args, **kwargs)
           ^^^^^^^^^^^^^^^^^^^^^^^^^^^^^
  File "<@beartype(src.model.iTransformer.forward) at 0x7fbcf2d21120>", line 66, in forward
  File "/data/student/k2110261/Multi-iTransformer/src/model.py", line 167, in forward
    assert x.shape[1:] == (self.lookback_len, self.num_variates)
           ^^^^^^^^^^^^^^^^^^^^^^^^^^^^^^^^^^^^^^^^^^^^^^^^^^^^^
AssertionError
[33m[W 2024-12-29 22:28:31,675][0m Trial 0 failed with value None.[0m
Traceback (most recent call last):
  File "/data/student/k2110261/Multi-iTransformer/roop_optuna.py", line 551, in <module>
    study.optimize(lambda trial: objective(trial, component, depth, dim), n_trials=30) #check
    ^^^^^^^^^^^^^^^^^^^^^^^^^^^^^^^^^^^^^^^^^^^^^^^^^^^^^^^^^^^^^^^^^^^^^^^^^^^^^^^^^^
  File "/home2/y2021/k2110261/.conda/envs/tensorflow/lib/python3.11/site-packages/optuna/study/study.py", line 475, in optimize
    _optimize(
  File "/home2/y2021/k2110261/.conda/envs/tensorflow/lib/python3.11/site-packages/optuna/study/_optimize.py", line 63, in _optimize
    _optimize_sequential(
  File "/home2/y2021/k2110261/.conda/envs/tensorflow/lib/python3.11/site-packages/optuna/study/_optimize.py", line 160, in _optimize_sequential
    frozen_trial = _run_trial(study, func, catch)
                   ^^^^^^^^^^^^^^^^^^^^^^^^^^^^^^
  File "/home2/y2021/k2110261/.conda/envs/tensorflow/lib/python3.11/site-packages/optuna/study/_optimize.py", line 248, in _run_trial
    raise func_err
  File "/home2/y2021/k2110261/.conda/envs/tensorflow/lib/python3.11/site-packages/optuna/study/_optimize.py", line 197, in _run_trial
    value_or_values = func(trial)
                      ^^^^^^^^^^^
  File "/data/student/k2110261/Multi-iTransformer/roop_optuna.py", line 551, in <lambda>
    study.optimize(lambda trial: objective(trial, component, depth, dim), n_trials=30) #check
                                 ^^^^^^^^^^^^^^^^^^^^^^^^^^^^^^^^^^^^^^^
  File "/data/student/k2110261/Multi-iTransformer/roop_optuna.py", line 114, in objective
    model, _, valid_loss = train(
                           ^^^^^^
  File "/data/student/k2110261/Multi-iTransformer/src/train.py", line 32, in train
    output = model(data)
             ^^^^^^^^^^^
  File "/home2/y2021/k2110261/.conda/envs/tensorflow/lib/python3.11/site-packages/torch/nn/modules/module.py", line 1736, in _wrapped_call_impl
    return self._call_impl(*args, **kwargs)
           ^^^^^^^^^^^^^^^^^^^^^^^^^^^^^^^^
  File "/home2/y2021/k2110261/.conda/envs/tensorflow/lib/python3.11/site-packages/torch/nn/modules/module.py", line 1747, in _call_impl
    return forward_call(*args, **kwargs)
           ^^^^^^^^^^^^^^^^^^^^^^^^^^^^^
  File "<@beartype(src.model.iTransformer.forward) at 0x7fbcf2d21120>", line 66, in forward
  File "/data/student/k2110261/Multi-iTransformer/src/model.py", line 167, in forward
    assert x.shape[1:] == (self.lookback_len, self.num_variates)
           ^^^^^^^^^^^^^^^^^^^^^^^^^^^^^^^^^^^^^^^^^^^^^^^^^^^^^
AssertionError
